<?xml version="1.0"?>
<robot name="myfirst">
	<link name="base_link">
		<visual>
			<geometry>
				<cylinder length="0.6" radius="0.2"/>
			</geometry>
		</visual>
	</link>
	<link name="right_leg">
		<visual>
			<geometry>
				<box size="0.6 .2 .1"/>
			</geometry>
			<origin rpy="0 1.57075 0" xyz="0 0 -0.3"/>
		</visual>
	</link>
<!-- 	<joint name="base_to_right_leg" type="fixed">
		<parent link="base_link"/>
		<child link="right_leg"/>
		<origin xyz="0.25 0 0.25"/>
	</joint> -->
	<joint name="base_to_right_leg" type="revolute">
		<parent link="base_link"/>
		<child link="right_leg"/>
		<axis xyz="1 0 0"/>
		<origin rpy="0 0 0" xyz="0.25 0 0.25"/>
		<limit effort="1000" lower="-0.5" upper="0.5" velocity="0.5" />
	</joint>

	<link name="left_leg">
		<visual>
			<geometry>
				<box size="0.6 .2 .1"/>
			</geometry>
			<origin rpy="0 1.57075 0" xyz="0 0 -0.3"/>
		</visual>
	</link>

	<joint name="base_to_left_leg" type="prismatic">
		<parent link="base_link"/>
		<child link="left_leg"/>
		<axis xyz="0 0 1"/>
		<origin rpy="0 0 0" xyz="-0.25 0 0.25"/>
		<limit effort="1000" lower="-0.5" upper="0.5" velocity="0.5" />
	</joint>
</robot>